Workbook

Sheet PLR_Absolut
C1: Geschlecht | E1: Altersgruppen | J1: Nationalität & Migrationshintergrund | O1: Familienstand | T1: Religion | W1: Wohnlagen
A2: RAUMID | B2: Insgesamt | C2: Einw m | D2: Einw w | E2: u15 | F2: 15u45 | G2: 45u65 | H2: 65+ | I2: Durchschnittsalter | J2: Deutsche | K2: Ausländer | L2: Einwohner ohne Migra | M2: Einwohner mit Migra | N2: darunter Deutsche mit Migra | O2: ledig | P2: verheiratet | Q2: verwitwet | R2: geschieden | S2: Lebenspartnerschaft | T2: Evangelisch | U2: Katholisch | V2: SonstigeKeine | W2: einfache Wohnlage | X2: mittlere Wohnlage | Y2: gute Wohnlage
A3: 01100101 | B3: 3469 | C3: 1803 | D3: 1666 | E3: 324 | F3: 1653 | G3: 792 | H3: 700 | I3: 43.6 | J3: 1987 | K3: 1482 | L3: 1137 | M3: 2332 | N3: 850 | O3: 1929 | P3: 1056 | Q3: 131 | R3: 320 | S3: 33 | T3: 268 | U3: 303 | V3: 2898 | W3: 0 | X3: 2442 | Y3: 1027
A4: 01100102 | B4: 2082 | C4: 1118 | D4: 964 | E4: 221 | F4: 1026 | G4: 544 | H4: 291 | I4: 42.1 | J4: 980 | K4: 1102 | L4: 579 | M4: 1503 | N4: 401 | O4: 1039 | P4: 867 | Q4: 45 | R4: 119 | S4: 12 | T4: 96 | U4: 159 | V4: 1827 | W4: 0 | X4: 16 | Y4: 2066
A5: 01100103 | B5: 5832 | C5: 3055 | D5: 2777 | E5: 620 | F5: 2779 | G5: 1327 | H5: 1106 | I5: 42.8 | J5: 3686 | K5: 2146 | L5: 2199 | M5: 3633 | N5: 1487 | O5: 3284 | P5: 1780 | Q5: 228 | R5: 486 | S5: 54 | T5: 485 | U5: 470 | V5: 4877 | W5: 1049 | X5: 4783 | Y5: 0
A6: 01100104 | B6: 4966 | C6: 2608 | D6: 2358 | E6: 644 | F6: 2653 | G6: 1192 | H6: 477 | I6: 37.8 | J6: 2936 | K6: 2030 | L6: 1589 | M6: 3377 | N6: 1347 | O6: 3138 | P6: 1437 | Q6: 80 | R6: 287 | S6: 24 | T6: 296 | U6: 284 | V6: 4386 | W6: 146 | X6: 4820 | Y6: 0
A7: 01100205 | B7: 2950 | C7: 1536 | D7: 1414 | E7: 287 | F7: 1514 | G7: 656 | H7: 493 | I7: 41.6 | J7: 1450 | K7: 1500 | L7: 877 | M7: 2073 | N7: 573 | O7: 1549 | P7: 1141 | Q7: 86 | R7: 168 | S7: 6 | T7: 140 | U7: 126 | V7: 2684 | W7: 0 | X7: 0 | Y7: 2950
A8: 01100206 | B8: 1901 | C8: 996 | D8: 905 | E8: 213 | F8: 917 | G8: 510 | H8: 261 | I8: 41.9 | J8: 1266 | K8: 635 | L8: 847 | M8: 1054 | N8: 419 | O8: 1052 | P8: 632 | Q8: 53 | R8: 153 | S8: 11 | T8: 122 | U8: 126 | V8: 1653 | W8: 0 | X8: 0 | Y8: 1901
A9: 01100207 | B9: 8907 | C9: 4524 | D9: 4383 | E9: 1028 | F9: 4193 | G9: 2054 | H9: 1632 | I9: 42.9 | J9: 5734 | K9: 3173 | L9: 3682 | M9: 5225 | N9: 2052 | O9: 4688 | P9: 3106 | Q9: 365 | R9: 692 | S9: 56 | T9: 495 | U9: 492 | V9: 7920 | W9: 3 | X9: 0 | Y9: 8904
A10: 01100308 | B10: 7363 | C10: 3768 | D10: 3595 | E10: 834 | F10: 3937 | G10: 1825 | H10: 767 | I10: 39.5 | J10: 4920 | K10: 2443 | L10: 3652 | M10: 3711 | N10: 1268 | O10: 4397 | P10: 2378 | Q10: 134 | R10: 424 | S10: 30 | T10: 671 | U10: 663 | V10: 6029 | W10: 0 | X10: 2934 | Y10: 4429
A11: 01100309 | B11: 12611 | C11: 6417 | D11: 6194 | E11: 1424 | F11: 6017 | G11: 3922 | H11: 1248 | I11: 40.4 | J11: 9028 | K11: 3583 | L11: 6865 | M11: 5746 | N11: 2163 | O11: 8003 | P11: 3465 | Q11: 213 | R11: 874 | S11: 56 | T11: 1371 | U11: 1006 | V11: 10234 | W11: 0 | X11: 0 | Y11: 12611
A12: 01100310 | B12: 10157 | C12: 5310 | D12: 4847 | E12: 1013 | F12: 5296 | G12: 2369 | H12: 1479 | I12: 41.5 | J12: 6315 | K12: 3842 | L12: 4391 | M12: 5766 | N12: 1924 | O12: 6273 | P12: 2663 | Q12: 348 | R12: 820 | S12: 53 | T12: 617 | U12: 621 | V12: 8919 | W12: 0 | X12: 62 | Y12: 10095
A13: 01100311 | B13: 9935 | C13: 4831 | D13: 5104 | E13: 1206 | F13: 4603 | G13: 1913 | H13: 2213 | I13: 43.3 | J13: 6438 | K13: 3497 | L13: 4333 | M13: 5602 | N13: 2105 | O13: 5377 | P13: 2977 | Q13: 638 | R13: 908 | S13: 35 | T13: 441 | U13: 376 | V13: 9118 | W13: 30 | X13: 9905 | Y13: 0
A14: 01100312 | B14: 10693 | C14: 5409 | D14: 5284 | E14: 1283 | F14: 5227 | G14: 2345 | H14: 1838 | I14: 42.5 | J14: 7071 | K14: 3622 | L14: 4905 | M14: 5788 | N14: 2166 | O14: 5726 | P14: 3649 | Q14: 481 | R14: 794 | S14: 43 | T14: 667 | U14: 470 | V14: 9556 | W14: 0 | X14: 310 | Y14: 10383
... A544: 12601236 | B544: 3216 | C544: 1620 | D544: 1596 | E544: 399 | F544: 1105 | G544: 833 | H544: 879 | I544: 46.7 | J544: 2545 | K544: 671 | L544: 1632 | M544: 1584 | N544: 913 | O544: 1310 | P544: 1460 | Q544: 235 | R544: 211 | S544: 0 | T544: 429 | U544: 277 | V544: 2510 | W544: 440 | X544: 2776 | Y544: 0

Sheet PLR_Relativ
A1: RAUMID | B1: Insgesamt | C1: Einw m | D1: Einw w | E1: u15 | F1: 15u45 | G1: 45u65 | H1: 65+ | I1: Durchschnittsalter | J1: Deutsche | K1: Ausländer | L1: Einwohner ohne Migra | M1: Einwohner mit Migra | N1: darunter Deutsche mit Migra | O1: ledig | P1: verheiratet | Q1: verwitwet | R1: geschieden | S1: Lebenspartnerschaft | T1: Evangelisch | U1: Katholisch | V1: SonstigeKeine | W1: einfache Wohnlage | X1: mittlere Wohnlage | Y1: gute Wohnlage
A2: 01100101 | B2: 100 | C2: 51.974632 | D2: 48.025368 | E2: 9.3398674 | F2: 47.65062 | G2: 22.830787 | H2: 20.178726 | I2: 0 | J2: 57.278755 | K2: 42.721245 | L2: 32.776016 | M2: 67.223984 | N2: 24.502739 | O2: 55.606803 | P2: 30.441049 | Q2: 3.7763044 | R2: 9.2245604 | S2: 0.95128279 | T2: 7.7255693 | U2: 8.7345056 | V2: 83.539925 | W2: 0 | X2: 70.394926 | Y2: 29.605074
A3: 01100102 | B3: 100 | C3: 53.698367 | D3: 46.301633 | E3: 10.614793 | F3: 49.279539 | G3: 26.128722 | H3: 13.976945 | I3: 0 | J3: 47.070125 | K3: 52.929875 | L3: 27.809798 | M3: 72.190202 | N3: 19.260327 | O3: 49.903939 | P3: 41.642651 | Q3: 2.1613833 | R3: 5.715658 | S3: 0.57636888 | T3: 4.610951 | U3: 7.6368876 | V3: 87.752161 | W3: 0 | X3: 0.76849183 | Y3: 99.231508
A4: 01100103 | B4: 100 | C4: 52.383402 | D4: 47.616598 | E4: 10.631001 | F4: 47.650892 | G4: 22.753772 | H4: 18.964335 | I4: 0 | J4: 63.203018 | K4: 36.796982 | L4: 37.705761 | M4: 62.294239 | N4: 25.497257 | O4: 56.310014 | P4: 30.521262 | Q4: 3.909465 | R4: 8.3333333 | S4: 0.92592593 | T4: 8.3161866 | U4: 8.0589849 | V4: 83.624829 | W4: 17.986968 | X4: 82.013032 | Y4: 0
A5: 01100104 | B5: 100 | C5: 52.517116 | D5: 47.482884 | E5: 12.968184 | F5: 53.423278 | G5: 24.003222 | H5: 9.6053161 | I5: 0 | J5: 59.12203 | K5: 40.87797 | L5: 31.997584 | M5: 68.002416 | N5: 27.124446 | O5: 63.18969 | P5: 28.93677 | Q5: 1.6109545 | R5: 5.7792992 | S5: 0.48328635 | T5: 5.9605316 | U5: 5.7188884 | V5: 88.32058 | W5: 2.9399919 | X5: 97.060008 | Y5: 0
A6: 01100205 | B6: 100 | C6: 52.067797 | D6: 47.932203 | E6: 9.7288136 | F6: 51.322034 | G6: 22.237288 | H6: 16.711864 | I6: 0 | J6: 49.152542 | K6: 50.847458 | L6: 29.728814 | M6: 70.271186 | N6: 19.423729 | O6: 52.508475 | P6: 38.677966 | Q6: 2.9152542 | R6: 5.6949153 | S6: 0.20338983 | T6: 4.7457627 | U6: 4.2711864 | V6: 90.983051 | W6: 0 | X6: 0 | Y6: 100
A7: 01100206 | B7: 100 | C7: 52.393477 | D7: 47.606523 | E7: 11.204629 | F7: 48.23777 | G7: 26.827985 | H7: 13.729616 | I7: 0 | J7: 66.596528 | K7: 33.403472 | L7: 44.555497 | M7: 55.444503 | N7: 22.041031 | O7: 55.339295 | P7: 33.24566 | Q7: 2.7880063 | R7: 8.0483956 | S7: 0.57864282 | T7: 6.4176749 | U7: 6.6280905 | V7: 86.954235 | W7: 0 | X7: 0 | Y7: 100
A8: 01100207 | B8: 100 | C8: 50.791512 | D8: 49.208488 | E8: 11.541484 | F8: 47.075334 | G8: 23.060514 | H8: 18.322668 | I8: 0 | J8: 64.376333 | K8: 35.623667 | L8: 41.338273 | M8: 58.661727 | N8: 23.03806 | O8: 52.632761 | P8: 34.871449 | Q8: 4.0979005 | R8: 7.7691703 | S8: 0.62871899 | T8: 5.5574267 | U8: 5.5237454 | V8: 88.918828 | W8: 0.033681374 | X8: 0 | Y8: 99.966319
A9: 01100308 | B9: 100 | C9: 51.174793 | D9: 48.825207 | E9: 11.326905 | F9: 53.470053 | G9: 24.786093 | H9: 10.41695 | I9: 0 | J9: 66.820589 | K9: 33.179411 | L9: 49.599348 | M9: 50.400652 | N9: 17.221241 | O9: 59.717506 | P9: 32.296618 | Q9: 1.8199104 | R9: 5.7585223 | S9: 0.40744262 | T9: 9.1131332 | U9: 9.0044819 | V9: 81.882385 | W9: 0 | X9: 39.847888 | Y9: 60.152112
A10: 01100309 | B10: 100 | C10: 50.884149 | D10: 49.115851 | E10: 11.291729 | F10: 47.712315 | G10: 31.099833 | H10: 9.8961224 | I10: 0 | J10: 71.588296 | K10: 28.411704 | L10: 54.436603 | M10: 45.563397 | N10: 17.151693 | O10: 63.460471 | P10: 27.476013 | Q10: 1.6890017 | R10: 6.9304575 | S10: 0.44405678 | T10: 10.871461 | U10: 7.9771628 | V10: 81.151376 | W10: 0 | X10: 0 | Y10: 100
A11: 01100310 | B11: 100 | C11: 52.279216 | D11: 47.720784 | E11: 9.9734173 | F11: 52.14138 | G11: 23.323816 | H11: 14.561386 | I11: 0 | J11: 62.17387 | K11: 37.82613 | L11: 43.231269 | M11: 56.768731 | N11: 18.942601 | O11: 61.760362 | P11: 26.218372 | Q11: 3.4262085 | R11: 8.07325 | S11: 0.52180762 | T11: 6.0746283 | U11: 6.11401 | V11: 87.811362 | W11: 0 | X11: 0.61041646 | Y11: 99.389584
A12: 01100311 | B12: 100 | C12: 48.626069 | D12: 51.373931 | E12: 12.138903 | F12: 46.331152 | G12: 19.255159 | H12: 22.274786 | I12: 0 | J12: 64.801208 | K12: 35.198792 | L12: 43.613488 | M12: 56.386512 | N12: 21.18772 | O12: 54.121792 | P12: 29.964771 | Q12: 6.4217413 | R12: 9.1394061 | S12: 0.35228988 | T12: 4.4388525 | U12: 3.7845999 | V12: 91.776548 | W12: 0.30196276 | X12: 99.698037 | Y12: 0
A13: 01100312 | B13: 100 | C13: 50.584495 | D13: 49.415505 | E13: 11.998504 | F13: 48.882446 | G13: 21.930235 | H13: 17.188815 | I13: 0 | J13: 66.127373 | K13: 33.872627 | L13: 45.871131 | M13: 54.128869 | N13: 20.256242 | O13: 53.549051 | P13: 34.125129 | Q13: 4.4982699 | R13: 7.4254185 | S13: 0.40213224 | T13: 6.2377256 | U13: 4.3953989 | V13: 89.366876 | W13: 0 | X13: 2.8990929 | Y13: 97.100907
... A116: 03400830 | B116: 100 | C116: 47.621112 | D116: 52.378888 | E116: 12.224992 | F116: 41.616994 | G116: 29.847188 | H116: 16.310827 | I116: 0 | J116: 86.387775 | K116: 13.612225 | L116: 77.197356 | M116: 22.802644 | N116: 9.1904194 | O116: 60.030346 | P116: 24.926845 | Q116: 3.8582421 | R116: 10.956974 | S116: 0.22759293 | T116: 8.9303132 | U116: 4.6168852 | V116: 86.452802 | W116: 0 | X116: 100 | Y116: 0
A117: 03400831 | B117: 0 | C117: #DIV/0! | D117: #DIV/0! | E117: #DIV/0! | F117: #DIV/0! | G117: #DIV/0! | H117: #DIV/0! | I117: 0 | J117: #DIV/0! | K117: #DIV/0! | L117: #DIV/0! | M117: #DIV/0! | N117: #DIV/0! | O117: #DIV/0! | P117: #DIV/0! | Q117: #DIV/0! | R117: #DIV/0! | S117: #DIV/0! | T117: #DIV/0! | U117: #DIV/0! | V117: #DIV/0! | W117: #DIV/0! | X117: #DIV/0! | Y117: #DIV/0!
A118: 03500932 | B118: 100 | C118: 50.206673 | D118: 49.793327 | E118: 14.555654 | F118: 44.700325 | G118: 24.165929 | H118: 16.578093 | I118: 0 | J118: 71.006791 | K118: 28.993209 | L118: 63.315619 | M118: 36.684381 | N118: 7.6911721 | O118: 58.827871 | P118: 26.719811 | Q118: 4.8272808 | R118: 9.5217006 | S118: 0.10333629 | T118: 6.1411278 | U118: 3.0705639 | V118: 90.788308 | W118: 16.740478 | X118: 83.259522 | Y118: 0
A119: 03500933 | B119: 100 | C119: 48.769603 | D119: 51.230397 | E119: 12.762973 | F119: 41.897233 | G119: 27.043223 | H119: 18.29657 | I119: 0 | J119: 83.97297 | K119: 16.02703 | L119: 74.423052 | M119: 25.576948 | N119: 9.5499171 | O119: 55.361469 | P119: 31.238047 | Q119: 5.4570955 | R119: 7.6628841 | S119: 0.28050491 | T119: 9.8176718 | U119: 5.1638404 | V119: 85.018488 | W119: 0 | X119: 57.363254 | Y119: 42.636746
A120: 03500934 | B120: 100 | C120: 50.925311 | D120: 49.074689 | E120: 14.510772 | F120: 49.61564 | G120: 25.870741 | H120: 10.002847 | I120: 0 | J120: 77.023821 | K120: 22.976179 | L120: 64.401632 | M120: 35.598368 | N120: 12.622188 | O120: 61.393186 | P120: 29.258802 | Q120: 2.2871785 | R120: 6.8045933 | S120: 0.25623992 | T120: 6.7096897 | U120: 5.6467685 | V120: 87.643542 | W120: 0 | X120: 100 | Y120: 0
A121: 03500935 | B121: 100 | C121: 49.636099 | D121: 50.363901 | E121: 14.643377 | F121: 48.762737 | G121: 27.321689 | H121: 9.272198 | I121: 0 | J121: 77.700146 | K121: 22.299854 | L121: 66.622999 | M121: 33.377001 | N121: 11.077147 | O121: 62.983988 | P121: 27.409025 | Q121: 2.154294 | R121: 7.2343523 | S121: 0.21834061 | T121: 8.5007278 | U121: 5.8078603 | V121: 85.691412 | W121: 0 | X121: 73.857351 | Y121: 26.142649
A122: 03500936 | B122: 100 | C122: 48.421779 | D122: 51.578221 | E122: 15.210101 | F122: 43.736437 | G122: 28.772934 | H122: 12.280529 | I122: 0 | J122: 82.136516 | K122: 17.863484 | L122: 71.522983 | M122: 28.477017 | N122: 10.613533 | O122: 60.258434 | P122: 28.043007 | Q122: 3.3339909 | R122: 8.1278359 | S122: 0.23673308 | T122: 9.4200039 | U122: 4.3105149 | V122: 86.269481 | W122: 0 | X122: 50.512922 | Y122: 49.487078
A123: 03501037 | B123: 100 | C123: 48.79887 | D123: 51.20113 | E123: 11.728686 | F123: 40.920867 | G123: 25.836081 | H123: 21.514366 | I123: 0 | J123: 81.288271 | K123: 18.711729 | L123: 73.327838 | M123: 26.672162 | N123: 7.9604333 | O123: 55.864343 | P123: 27.272727 | Q123: 6.9948187 | R123: 9.7974564 | S123: 0.070654734 | T123: 7.4894018 | U123: 3.6033914 | V123: 88.907207 | W123: 8.089967 | X123: 91.910033 | Y123: 0
A124: 03501038 | B124: 100 | C124: 46.814078 | D124: 53.185922 | E124: 13.80348 | F124: 36.621745 | G124: 26.246238 | H124: 23.328536 | I124: 0 | J124: 84.796546 | K124: 15.203454 | L124: 76.239696 | M124: 23.760304 | N124: 8.5568494 | O124: 48.789742 | P124: 35.535784 | Q124: 6.8297789 | R124: 8.596101 | S124: 0.24859348 | T124: 5.8746565 | U124: 3.3102185 | V124: 90.815125 | W124: 0.4055999 | X124: 99.5944 | Y124: 0
A125: 03601139 | B125: 100 | C125: 49.790589 | D125: 50.209411 | E125: 12.170485 | F125: 54.175905 | G125: 23.429416 | H125: 10.224193 | I125: 0 | J125: 71.101256 | K125: 28.898744 | L125: 56.122198 | M125: 43.877802 | N125: 14.979059 | O125: 64.153732 | P125: 25.301798 | Q125: 3.7447647 | R125: 6.5533383 | S125: 0.2463661 | T125: 8.4257206 | U125: 5.5678739 | V125: 86.006406 | W125: 0.07390983 | X125: 95.097315 | Y125: 4.8287756
A126: 03601140 | B126: 100 | C126: 51.424263 | D126: 48.575737 | E126: 11.980563 | F126: 53.770107 | G126: 27.781501 | H126: 6.4678284 | I126: 0 | J126: 75.08378 | K126: 24.91622 | L126: 62.399464 | M126: 37.600536 | N126: 12.684316 | O126: 67.979223 | P126: 24.564343 | Q126: 1.0723861 | R126: 5.7808311 | S126: 0.60321716 | T126: 9.5844504 | U126: 6.233244 | V126: 84.182306 | W126: 0 | X126: 89.795576 | Y126: 10.204424
A127: 03601141 | B127: 100 | C127: 49.491094 | D127: 50.508906 | E127: 13.076053 | F127: 53.633022 | G127: 26.010744 | H127: 7.2801809 | I127: 0 | J127: 72.702856 | K127: 27.297144 | L127: 59.329941 | M127: 40.670059 | N127: 13.372915 | O127: 68.052021 | P127: 24.46989 | Q127: 1.6963528 | R127: 5.4848742 | S127: 0.29686175 | T127: 9.4571671 | U127: 7.4074074 | V127: 83.135426 | W127: 0 | X127: 41.687871 | Y127: 58.312129
A128: 03601142 | B128: 100 | C128: 49.926457 | D128: 50.073543 | E128: 11.904762 | F128: 51.994852 | G128: 29.996323 | H128: 6.1040632 | I128: 0 | J128: 73.708402 | K128: 26.291598 | L128: 59.643317 | M128: 40.356683 | N128: 14.065085 | O128: 70.095606 | P128: 23.018937 | Q128: 1.1858798 | R128: 5.3502482 | S128: 0.34932892 | T128: 10.875161 | U128: 7.9886008 | V128: 81.136238 | W128: 0 | X128: 0 | Y128: 100
A129: 03601243 | B129: 100 | C129: 49.252659 | D129: 50.747341 | E129: 11.957459 | F129: 51.020408 | G129: 27.321069 | H129: 9.7010635 | I129: 0 | J129: 79.706812 | K129: 20.293188 | L129: 65.751653 | M129: 34.248347 | N129: 13.95516 | O129: 67.361311 | P129: 24.00115 | Q129: 2.0264444 | R129: 6.0649612 | S129: 0.54613395 | T129: 9.1693015 | U129: 7.171601 | V129: 83.659097 | W129: 0 | X129: 74.130497 | Y129: 25.869503
... A261: 06200317 | B261: 100 | C261: 48.54292 | D261: 51.45708 | E261: 13.066202 | F261: 28.888185 | G261: 28.729807 | H261: 29.315806 | I261: 0 | J261: 88.644283 | K261: 11.355717 | L261: 74.659487 | M261: 25.340513 | N261: 13.984796 | O261: 41.178334 | P261: 42.841305 | Q261: 7.0953437 | R261: 8.742477 | S261: 0.14254039 | T261: 20.003168 | U261: 11.086475 | V261: 68.910358 | W261: 3.8169148 | X261: 96.183085 | Y261: 0
A262: 06200318 | B262: 0 | C262: #DIV/0! | D262: #DIV/0! | E262: #DIV/0! | F262: #DIV/0! | G262: #DIV/0! | H262: #DIV/0! | I262: 0 | J262: #DIV/0! | K262: #DIV/0! | L262: #DIV/0! | M262: #DIV/0! | N262: #DIV/0! | O262: #DIV/0! | P262: #DIV/0! | Q262: #DIV/0! | R262: #DIV/0! | S262: #DIV/0! | T262: #DIV/0! | U262: #DIV/0! | V262: #DIV/0! | W262: #DIV/0! | X262: #DIV/0! | Y262: #DIV/0!
A263: 06200419 | B263: 100 | C263: 47.308719 | D263: 52.691281 | E263: 13.011566 | F263: 40.302491 | G263: 22.508897 | H263: 24.177046 | I263: 0 | J263: 69.372776 | K263: 30.627224 | L263: 41.837189 | M263: 58.162811 | N263: 27.535587 | O263: 47.731317 | P263: 35.431495 | Q263: 7.2508897 | R263: 9.519573 | S263: 0.066725979 | T263: 11.410142 | U263: 9.7864769 | V263: 78.803381 | W263: 53.002669 | X263: 46.997331 | Y263: 0
A264: 06200420 | B264: 100 | C264: 47.123708 | D264: 52.876292 | E264: 12.761798 | F264: 31.443731 | G264: 28.120637 | H264: 27.673834 | I264: 0 | J264: 82.895839 | K264: 17.104161 | L264: 67.048311 | M264: 32.951689 | N264: 15.847529 | O264: 42.725496 | P264: 38.899749 | Q264: 7.8609327 | R264: 10.471935 | S264: 0.041887741 | T264: 18.011729 | U264: 8.3775482 | V264: 73.610723 | W264: 52.555152 | X264: 47.444848 | Y264: 0
A265: 06200421 | B265: 100 | C265: 47.279793 | D265: 52.720207 | E265: 11.446067 | F265: 34.102685 | G265: 26.165803 | H265: 28.285445 | I265: 0 | J265: 80.440415 | K265: 19.559585 | L265: 66.686293 | M265: 33.313707 | N265: 13.754122 | O265: 45.254357 | P265: 37.411682 | Q265: 7.3598681 | R265: 9.8916627 | S265: 0.082430523 | T265: 18.982572 | U265: 8.8200659 | V265: 72.197362 | W265: 0.035327367 | X265: 41.580311 | Y265: 58.384362
A266: 06200422 | B266: 100 | C266: 46.961953 | D266: 53.038047 | E266: 12.478705 | F266: 33.233958 | G266: 26.575809 | H266: 27.711528 | I266: 0 | J266: 84.270301 | K266: 15.729699 | L266: 73.069279 | M266: 26.930721 | N266: 11.201022 | O266: 43.46962 | P266: 41.851221 | Q266: 7.0840432 | R266: 7.4673481 | S266: 0.12776831 | T266: 21.607041 | U266: 7.8222601 | V266: 70.570698 | W266: 0 | X266: 92.603634 | Y266: 7.3963657
A267: 06200423 | B267: 100 | C267: 46.827618 | D267: 53.172382 | E267: 13.972475 | F267: 29.30954 | G267: 26.930254 | H267: 29.78773 | I267: 0 | J267: 85.094472 | K267: 14.905528 | L267: 66.806625 | M267: 33.193375 | N267: 18.287847 | O267: 39.958013 | P267: 44.669932 | Q267: 7.371122 | R267: 7.8843014 | S267: 0.11663168 | T267: 17.961278 | U267: 10.263588 | V267: 71.775134 | W267: 0.13995801 | X267: 99.860042 | Y267: 0
A268: 06300524 | B268: 100 | C268: 48.484311 | D268: 51.515689 | E268: 13.845063 | F268: 29.356497 | G268: 27.176033 | H268: 29.622407 | I268: 0 | J268: 84.311292 | K268: 15.688708 | L268: 70.891686 | M268: 29.108314 | N268: 13.419606 | O268: 43.556107 | P268: 40.826095 | Q268: 7.4454884 | R268: 7.9418543 | S268: 0.23045559 | T268: 22.442829 | U268: 8.9345861 | V268: 68.622585 | W268: 0 | X268: 89.257224 | Y268: 10.742776
A269: 06300525 | B269: 100 | C269: 45.978782 | D269: 54.021218 | E269: 11.943874 | F269: 35.797399 | G269: 27.566735 | H269: 24.691992 | I269: 0 | J269: 81.776181 | K269: 18.223819 | L269: 67.231348 | M269: 32.768652 | N269: 14.544832 | O269: 47.535934 | P269: 33.658453 | Q269: 6.2970568 | R269: 12.457221 | S269: 0.051334702 | T269: 18.12115 | U269: 7.7002053 | V269: 74.178645 | W269: 0 | X269: 100 | Y269: 0
A270: 06300526 | B270: 100 | C270: 48.991696 | D270: 51.008304 | E270: 13.6121 | F270: 36.892052 | G270: 26.868327 | H270: 22.627521 | I270: 0 | J270: 81.346382 | K270: 18.653618 | L270: 63.879004 | M270: 36.120996 | N270: 17.467378 | O270: 47.686833 | P270: 38.048636 | Q270: 5.1601423 | R270: 8.7188612 | S270: 0.38552788 | T270: 17.200474 | U270: 11.595492 | V270: 71.204033 | W270: 0 | X270: 3.9145907 | Y270: 96.085409
A271: 06300527 | B271: 100 | C271: 46.006802 | D271: 53.993198 | E271: 11.586725 | F271: 35.475548 | G271: 26.633048 | H271: 26.304679 | I271: 0 | J271: 84.132755 | K271: 15.867245 | L271: 66.846488 | M271: 33.153512 | N271: 17.286267 | O271: 46.38208 | P271: 36.742113 | Q271: 5.992729 | R271: 10.847895 | S271: 0.035182362 | T271: 18.529377 | U271: 8.7604081 | V271: 72.710215 | W271: 0.070364724 | X271: 21.449513 | Y271: 78.480122
A272: 06300528 | B272: 100 | C272: 46.096247 | D272: 53.903753 | E272: 12.172404 | F272: 28.399233 | G272: 26.362889 | H272: 33.065473 | I272: 0 | J272: 86.841384 | K272: 13.158616 | L272: 72.002557 | M272: 27.997443 | N272: 14.838828 | O272: 40.462058 | P272: 41.950507 | Q272: 9.7799288 | R272: 7.6979271 | S272: 0.10957903 | T272: 24.764862 | U272: 10.410008 | V272: 64.82513 | W272: 0.11871062 | X272: 60.1041 | Y272: 39.777189
A273: 06300629 | B273: 100 | C273: 47.207258 | D273: 52.792742 | E273: 10.391267 | F273: 36.815991 | G273: 27.33201 | H273: 25.460731 | I273: 0 | J273: 82.435498 | K273: 17.564502 | L273: 67.252623 | M273: 32.747377 | N273: 15.182875 | O273: 47.349022 | P273: 38.106039 | Q273: 5.8406578 | R273: 8.3215197 | S273: 0.38276155 | T273: 20.187128 | U273: 10.136093 | V273: 69.676779 | W273: 0 | X273: 0.14176354 | Y273: 99.858236
...

Sheet Bezirk_Absolut
A1: Bezirk | C1: Geschlecht | E1: Altersgruppen | J1: Nationalität & Migrationshintergrund | O1: Familienstand | T1: Religion | W1: Wohnlagen
A2: Bezirk | B2: Insgesamt | C2: Einw m | D2: Einw w | E2: u15 | F2: 15u45 | G2: 45u65 | H2: 65+ | I2: Durchschnittsalter | J2: Deutsche | K2: Ausländer | L2: Einwohner ohne Migra | M2: Einwohner mit Migra | N2: darunter Deutsche mit Migra | O2: ledig | P2: verheiratet | Q2: verwitwet | R2: geschieden | S2: Lebenspartnerschaft | T2: Evangelisch | U2: Katholisch | V2: SonstigeKeine | W2: einfache Wohnlage | X2: mittlere Wohnlage | Y2: gute Wohnlage
A3: 01 | B3: 397879 | C3: 205205 | D3: 192674 | E3: 48418 | F3: 204655 | G3: 92359 | H3: 52447 | I3: 39.8 | J3: 251225 | K3: 146654 | L3: 161907 | M3: 235972 | N3: 89318 | O3: 241785 | P3: 112967 | Q3: 12982 | R3: 28984 | S3: 1161 | T3: 33823 | U3: 27083 | V3: 336973 | W3: 243389 | X3: 59238 | Y3: 95252
A4: 02 | B4: 292789 | C4: 150193 | D4: 142596 | E4: 35298 | F4: 150526 | G4: 73794 | H4: 33171 | I4: 39.7 | J4: 203249 | K4: 89540 | L4: 144645 | M4: 148144 | N4: 58604 | O4: 188286 | P4: 76380 | Q4: 7394 | R4: 19712 | S4: 1017 | T4: 23205 | U4: 16489 | V4: 253095 | W4: 76922 | X4: 145238 | Y4: 70629
A5: 03 | B5: 428900 | C5: 210601 | D5: 218299 | E5: 59208 | F5: 184017 | G5: 120987 | H5: 64688 | I5: 41.8 | J5: 344549 | K5: 84351 | L5: 295213 | M5: 133687 | N5: 49336 | O5: 247981 | P5: 130532 | Q5: 16991 | R5: 32276 | S5: 1120 | T5: 40244 | U5: 22976 | V5: 365680 | W5: 27763 | X5: 266671 | Y5: 134466
A6: 04 | B6: 343625 | C6: 166131 | D6: 177494 | E6: 38689 | F6: 139319 | G6: 85905 | H6: 79712 | I6: 45.2 | J6: 251140 | K6: 92485 | L6: 180951 | M6: 162674 | N6: 70189 | O6: 178704 | P6: 113773 | Q6: 17706 | R6: 32277 | S6: 1165 | T6: 46487 | U6: 30958 | V6: 266180 | W6: 27997 | X6: 105455 | Y6: 210173
A7: 05 | B7: 261266 | C7: 128627 | D7: 132639 | E7: 39881 | F7: 102021 | G7: 65240 | H7: 54124 | I7: 43 | J7: 190805 | K7: 70461 | L7: 137638 | M7: 123628 | N7: 53167 | O7: 128258 | P7: 93711 | Q7: 15737 | R7: 23305 | S7: 255 | T7: 38489 | U7: 20303 | V7: 202474 | W7: 197470 | X7: 55146 | Y7: 8650
A8: 06 | B8: 309338 | C8: 146247 | D8: 163091 | E8: 38925 | F8: 107366 | G8: 82980 | H8: 80067 | I8: 46.6 | J8: 254709 | K8: 54629 | L8: 204360 | M8: 104978 | N8: 50349 | O8: 143601 | P8: 117449 | Q8: 20005 | R8: 27761 | S8: 522 | T8: 59713 | U8: 28914 | V8: 220711 | W8: 6605 | X8: 159137 | Y8: 143596
A9: 07 | B9: 358835 | C9: 176551 | D9: 182284 | E9: 46432 | F9: 143809 | G9: 92222 | H9: 76372 | I9: 44.1 | J9: 274702 | K9: 84133 | L9: 201765 | M9: 157070 | N9: 72937 | O9: 185786 | P9: 121484 | Q9: 19181 | R9: 31135 | S9: 1249 | T9: 51267 | U9: 30865 | V9: 276703 | W9: 89932 | X9: 209352 | Y9: 59551
A10: 08 | B10: 331623 | C10: 166220 | D10: 165403 | E10: 44631 | F10: 147731 | G10: 81257 | H10: 58004 | I10: 42 | J10: 236178 | K10: 95445 | L10: 156739 | M10: 174884 | N10: 79439 | O10: 183270 | P10: 104811 | Q10: 16440 | R10: 26540 | S10: 562 | T10: 37072 | U10: 23110 | V10: 271441 | W10: 272400 | X10: 59223 | Y10: 0
A11: 09 | B11: 302686 | C11: 149957 | D11: 152729 | E11: 42244 | F11: 124546 | G11: 75206 | H11: 60690 | I11: 43.4 | J11: 248677 | K11: 54009 | L11: 218855 | M11: 83831 | N11: 29822 | O11: 157949 | P11: 102180 | Q11: 17213 | R11: 24930 | S11: 414 | T11: 22397 | U11: 11591 | V11: 268698 | W11: 75740 | X11: 208701 | Y11: 18245
A12: 10 | B12: 296687 | C12: 147944 | D12: 148743 | E12: 45508 | F12: 112914 | G12: 72416 | H12: 65849 | I12: 43.4 | J12: 236759 | K12: 59928 | L12: 203329 | M12: 93358 | N12: 33430 | O12: 148030 | P12: 105397 | Q12: 16275 | R12: 26735 | S12: 250 | T12: 16066 | U12: 10051 | V12: 270570 | W12: 149454 | X12: 135809 | Y12: 11424
A13: 11 | B13: 318261 | C13: 158399 | D13: 159862 | E13: 46881 | F13: 140305 | G13: 71297 | H13: 59778 | I13: 41.8 | J13: 236371 | K13: 81890 | L13: 195434 | M13: 122827 | N13: 40937 | O13: 177407 | P13: 98274 | Q13: 16188 | R13: 25946 | S13: 446 | T13: 16936 | U13: 11841 | V13: 289484 | W13: 124123 | X13: 177512 | Y13: 16626
A14: 12 | B14: 271755 | C14: 134600 | D14: 137155 | E14: 38062 | F14: 101227 | G14: 69701 | H14: 62765 | I14: 44.6 | J14: 208861 | K14: 62894 | L14: 157615 | M14: 114140 | N14: 51246 | O14: 129720 | P14: 99561 | Q14: 17467 | R14: 24726 | S14: 281 | T14: 44115 | U14: 22551 | V14: 205089 | W14: 146587 | X14: 95667 | Y14: 29501
A15: 00 | B15: 3913644 | C15: 1940675 | D15: 1972969 | E15: 524177 | F15: 1658436 | G15: 983364 | H15: 747667 | I15: 42.9 | J15: 2937225 | K15: 976419 | L15: 2258451 | M15: 1655193 | N15: 678774 | O15: 2110777 | P15: 1276519 | Q15: 193579 | R15: 324327 | S15: 8442 | T15: 429814 | U15: 256732 | V15: 3227098 | W15: 1438382 | X15: 1677149 | Y15: 798113

Sheet Bezirk_Relativ
A1: Bezirk | B1: Insgesamt | C1: Einw m | D1: Einw w | E1: u15 | F1: 15u45 | G1: 45u65 | H1: 65+ | I1: Durchschnittsalter | J1: Deutsche | K1: Ausländer | L1: Einwohner ohne Migra | M1: Einwohner mit Migra | N1: darunter Deutsche mit Migra | O1: ledig | P1: verheiratet | Q1: verwitwet | R1: geschieden | S1: Lebenspartnerschaft | T1: Evangelisch | U1: Katholisch | V1: SonstigeKeine | W1: einfache Wohnlage | X1: mittlere Wohnlage | Y1: gute Wohnlage
A2: 01 | B2: =Bezirk_Absolut!B3/Bezirk_Absolut!$B3 -> 1 | C2: =Bezirk_Absolut!C3/Bezirk_Absolut!$B3 -> 0.51574725 | D2: =Bezirk_Absolut!D3/Bezirk_Absolut!$B3 -> 0.48425275 | E2: =Bezirk_Absolut!E3/Bezirk_Absolut!$B3 -> 0.12169026 | F2: =Bezirk_Absolut!F3/Bezirk_Absolut!$B3 -> 0.51436492 | G2: =Bezirk_Absolut!G3/Bezirk_Absolut!$B3 -> 0.23212836 | H2: =Bezirk_Absolut!H3/Bezirk_Absolut!$B3 -> 0.13181646 | J2: =Bezirk_Absolut!J3/Bezirk_Absolut!$B3 -> 0.63141055 | K2: =Bezirk_Absolut!K3/Bezirk_Absolut!$B3 -> 0.36858945 | L2: =Bezirk_Absolut!L3/Bezirk_Absolut!$B3 -> 0.40692522 | M2: =Bezirk_Absolut!M3/Bezirk_Absolut!$B3 -> 0.59307478 | N2: =Bezirk_Absolut!N3/Bezirk_Absolut!$B3 -> 0.22448533 | O2: =Bezirk_Absolut!O3/Bezirk_Absolut!$B3 -> 0.60768475 | P2: =Bezirk_Absolut!P3/Bezirk_Absolut!$B3 -> 0.283923 | Q2: =Bezirk_Absolut!Q3/Bezirk_Absolut!$B3 -> 0.03262801 | ... Y2: =Bezirk_Absolut!Y3/Bezirk_Absolut!$B3 -> 0.23939942
A3: 02 | B3: =Bezirk_Absolut!B4/Bezirk_Absolut!$B4 -> 1 | C3: =Bezirk_Absolut!C4/Bezirk_Absolut!$B4 -> 0.51297351 | D3: =Bezirk_Absolut!D4/Bezirk_Absolut!$B4 -> 0.48702649 | E3: =Bezirk_Absolut!E4/Bezirk_Absolut!$B4 -> 0.12055781 | F3: =Bezirk_Absolut!F4/Bezirk_Absolut!$B4 -> 0.51411084 | G3: =Bezirk_Absolut!G4/Bezirk_Absolut!$B4 -> 0.25203816 | H3: =Bezirk_Absolut!H4/Bezirk_Absolut!$B4 -> 0.11329319 | J3: =Bezirk_Absolut!J4/Bezirk_Absolut!$B4 -> 0.6941825 | K3: =Bezirk_Absolut!K4/Bezirk_Absolut!$B4 -> 0.3058175 | L3: =Bezirk_Absolut!L4/Bezirk_Absolut!$B4 -> 0.49402471 | M3: =Bezirk_Absolut!M4/Bezirk_Absolut!$B4 -> 0.50597529 | N3: =Bezirk_Absolut!N4/Bezirk_Absolut!$B4 -> 0.20015779 | O3: =Bezirk_Absolut!O4/Bezirk_Absolut!$B4 -> 0.64307744 | P3: =Bezirk_Absolut!P4/Bezirk_Absolut!$B4 -> 0.26087046 | Q3: =Bezirk_Absolut!Q4/Bezirk_Absolut!$B4 -> 0.025253681 | ... Y3: =Bezirk_Absolut!Y4/Bezirk_Absolut!$B4 -> 0.24122832
A4: 03 | B4: =Bezirk_Absolut!B5/Bezirk_Absolut!$B5 -> 1 | C4: =Bezirk_Absolut!C5/Bezirk_Absolut!$B5 -> 0.49102588 | D4: =Bezirk_Absolut!D5/Bezirk_Absolut!$B5 -> 0.50897412 | E4: =Bezirk_Absolut!E5/Bezirk_Absolut!$B5 -> 0.13804616 | F4: =Bezirk_Absolut!F5/Bezirk_Absolut!$B5 -> 0.42904407 | G4: =Bezirk_Absolut!G5/Bezirk_Absolut!$B5 -> 0.28208673 | H4: =Bezirk_Absolut!H5/Bezirk_Absolut!$B5 -> 0.15082304 | J4: =Bezirk_Absolut!J5/Bezirk_Absolut!$B5 -> 0.80333178 | K4: =Bezirk_Absolut!K5/Bezirk_Absolut!$B5 -> 0.19666822 | L4: =Bezirk_Absolut!L5/Bezirk_Absolut!$B5 -> 0.68830263 | M4: =Bezirk_Absolut!M5/Bezirk_Absolut!$B5 -> 0.31169737 | N4: =Bezirk_Absolut!N5/Bezirk_Absolut!$B5 -> 0.11502914 | O4: =Bezirk_Absolut!O5/Bezirk_Absolut!$B5 -> 0.57817906 | P4: =Bezirk_Absolut!P5/Bezirk_Absolut!$B5 -> 0.30434134 | Q4: =Bezirk_Absolut!Q5/Bezirk_Absolut!$B5 -> 0.039615295 | ... Y4: =Bezirk_Absolut!Y5/Bezirk_Absolut!$B5 -> 0.31351364
A5: 04 | B5: =Bezirk_Absolut!B6/Bezirk_Absolut!$B6 -> 1 | C5: =Bezirk_Absolut!C6/Bezirk_Absolut!$B6 -> 0.48346599 | D5: =Bezirk_Absolut!D6/Bezirk_Absolut!$B6 -> 0.51653401 | E5: =Bezirk_Absolut!E6/Bezirk_Absolut!$B6 -> 0.11259076 | F5: =Bezirk_Absolut!F6/Bezirk_Absolut!$B6 -> 0.40543907 | G5: =Bezirk_Absolut!G6/Bezirk_Absolut!$B6 -> 0.24999636 | H5: =Bezirk_Absolut!H6/Bezirk_Absolut!$B6 -> 0.23197381 | J5: =Bezirk_Absolut!J6/Bezirk_Absolut!$B6 -> 0.73085486 | K5: =Bezirk_Absolut!K6/Bezirk_Absolut!$B6 -> 0.26914514 | L5: =Bezirk_Absolut!L6/Bezirk_Absolut!$B6 -> 0.5265944 | M5: =Bezirk_Absolut!M6/Bezirk_Absolut!$B6 -> 0.4734056 | N5: =Bezirk_Absolut!N6/Bezirk_Absolut!$B6 -> 0.20426046 | O5: =Bezirk_Absolut!O6/Bezirk_Absolut!$B6 -> 0.52005529 | P5: =Bezirk_Absolut!P6/Bezirk_Absolut!$B6 -> 0.3310964 | Q5: =Bezirk_Absolut!Q6/Bezirk_Absolut!$B6 -> 0.051527101 | ... Y5: =Bezirk_Absolut!Y6/Bezirk_Absolut!$B6 -> 0.61163478
A6: 05 | B6: =Bezirk_Absolut!B7/Bezirk_Absolut!$B7 -> 1 | C6: =Bezirk_Absolut!C7/Bezirk_Absolut!$B7 -> 0.492322 | D6: =Bezirk_Absolut!D7/Bezirk_Absolut!$B7 -> 0.507678 | E6: =Bezirk_Absolut!E7/Bezirk_Absolut!$B7 -> 0.1526452 | F6: =Bezirk_Absolut!F7/Bezirk_Absolut!$B7 -> 0.39048709 | G6: =Bezirk_Absolut!G7/Bezirk_Absolut!$B7 -> 0.24970719 | H6: =Bezirk_Absolut!H7/Bezirk_Absolut!$B7 -> 0.20716052 | J6: =Bezirk_Absolut!J7/Bezirk_Absolut!$B7 -> 0.73030934 | K6: =Bezirk_Absolut!K7/Bezirk_Absolut!$B7 -> 0.26969066 | L6: =Bezirk_Absolut!L7/Bezirk_Absolut!$B7 -> 0.52681176 | M6: =Bezirk_Absolut!M7/Bezirk_Absolut!$B7 -> 0.47318824 | N6: =Bezirk_Absolut!N7/Bezirk_Absolut!$B7 -> 0.20349758 | O6: =Bezirk_Absolut!O7/Bezirk_Absolut!$B7 -> 0.49090965 | P6: =Bezirk_Absolut!P7/Bezirk_Absolut!$B7 -> 0.35868043 | Q6: =Bezirk_Absolut!Q7/Bezirk_Absolut!$B7 -> 0.060233632 | ... Y6: =Bezirk_Absolut!Y7/Bezirk_Absolut!$B7 -> 0.03310802
A7: 06 | B7: =Bezirk_Absolut!B8/Bezirk_Absolut!$B8 -> 1 | C7: =Bezirk_Absolut!C8/Bezirk_Absolut!$B8 -> 0.47277412 | D7: =Bezirk_Absolut!D8/Bezirk_Absolut!$B8 -> 0.52722588 | E7: =Bezirk_Absolut!E8/Bezirk_Absolut!$B8 -> 0.12583323 | F7: =Bezirk_Absolut!F8/Bezirk_Absolut!$B8 -> 0.34708313 | G7: =Bezirk_Absolut!G8/Bezirk_Absolut!$B8 -> 0.26825026 | H7: =Bezirk_Absolut!H8/Bezirk_Absolut!$B8 -> 0.25883338 | J7: =Bezirk_Absolut!J8/Bezirk_Absolut!$B8 -> 0.82340029 | K7: =Bezirk_Absolut!K8/Bezirk_Absolut!$B8 -> 0.17659971 | L7: =Bezirk_Absolut!L8/Bezirk_Absolut!$B8 -> 0.66063659 | M7: =Bezirk_Absolut!M8/Bezirk_Absolut!$B8 -> 0.33936341 | N7: =Bezirk_Absolut!N8/Bezirk_Absolut!$B8 -> 0.16276371 | O7: =Bezirk_Absolut!O8/Bezirk_Absolut!$B8 -> 0.46422037 | P7: =Bezirk_Absolut!P8/Bezirk_Absolut!$B8 -> 0.37967854 | Q7: =Bezirk_Absolut!Q8/Bezirk_Absolut!$B8 -> 0.064670361 | ... Y7: =Bezirk_Absolut!Y8/Bezirk_Absolut!$B8 -> 0.4642042
A8: 07 | B8: =Bezirk_Absolut!B9/Bezirk_Absolut!$B9 -> 1 | C8: =Bezirk_Absolut!C9/Bezirk_Absolut!$B9 -> 0.49201165 | D8: =Bezirk_Absolut!D9/Bezirk_Absolut!$B9 -> 0.50798835 | E8: =Bezirk_Absolut!E9/Bezirk_Absolut!$B9 -> 0.12939652 | F8: =Bezirk_Absolut!F9/Bezirk_Absolut!$B9 -> 0.40076637 | G8: =Bezirk_Absolut!G9/Bezirk_Absolut!$B9 -> 0.25700392 | H8: =Bezirk_Absolut!H9/Bezirk_Absolut!$B9 -> 0.2128332 | J8: =Bezirk_Absolut!J9/Bezirk_Absolut!$B9 -> 0.76553848 | K8: =Bezirk_Absolut!K9/Bezirk_Absolut!$B9 -> 0.23446152 | L8: =Bezirk_Absolut!L9/Bezirk_Absolut!$B9 -> 0.56227793 | M8: =Bezirk_Absolut!M9/Bezirk_Absolut!$B9 -> 0.43772207 | N8: =Bezirk_Absolut!N9/Bezirk_Absolut!$B9 -> 0.20326055 | O8: =Bezirk_Absolut!O9/Bezirk_Absolut!$B9 -> 0.51774771 | P8: =Bezirk_Absolut!P9/Bezirk_Absolut!$B9 -> 0.33855114 | Q8: =Bezirk_Absolut!Q9/Bezirk_Absolut!$B9 -> 0.053453537 | ... Y8: =Bezirk_Absolut!Y9/Bezirk_Absolut!$B9 -> 0.1659565
A9: 08 | B9: =Bezirk_Absolut!B10/Bezirk_Absolut!$B10 -> 1 | C9: =Bezirk_Absolut!C10/Bezirk_Absolut!$B10 -> 0.50123182 | D9: =Bezirk_Absolut!D10/Bezirk_Absolut!$B10 -> 0.49876818 | E9: =Bezirk_Absolut!E10/Bezirk_Absolut!$B10 -> 0.13458355 | F9: =Bezirk_Absolut!F10/Bezirk_Absolut!$B10 -> 0.44547875 | G9: =Bezirk_Absolut!G10/Bezirk_Absolut!$B10 -> 0.24502824 | H9: =Bezirk_Absolut!H10/Bezirk_Absolut!$B10 -> 0.17490946 | J9: =Bezirk_Absolut!J10/Bezirk_Absolut!$B10 -> 0.71218824 | K9: =Bezirk_Absolut!K10/Bezirk_Absolut!$B10 -> 0.28781176 | L9: =Bezirk_Absolut!L10/Bezirk_Absolut!$B10 -> 0.47264213 | M9: =Bezirk_Absolut!M10/Bezirk_Absolut!$B10 -> 0.52735787 | N9: =Bezirk_Absolut!N10/Bezirk_Absolut!$B10 -> 0.23954611 | O9: =Bezirk_Absolut!O10/Bezirk_Absolut!$B10 -> 0.55264562 | P9: =Bezirk_Absolut!P10/Bezirk_Absolut!$B10 -> 0.31605468 | Q9: =Bezirk_Absolut!Q10/Bezirk_Absolut!$B10 -> 0.049574366 | ... Y9: =Bezirk_Absolut!Y10/Bezirk_Absolut!$B10 -> 0
A10: 09 | B10: =Bezirk_Absolut!B11/Bezirk_Absolut!$B11 -> 1 | C10: =Bezirk_Absolut!C11/Bezirk_Absolut!$B11 -> 0.495421 | D10: =Bezirk_Absolut!D11/Bezirk_Absolut!$B11 -> 0.504579 | E10: =Bezirk_Absolut!E11/Bezirk_Absolut!$B11 -> 0.13956377 | F10: =Bezirk_Absolut!F11/Bezirk_Absolut!$B11 -> 0.41146931 | G10: =Bezirk_Absolut!G11/Bezirk_Absolut!$B11 -> 0.2484621 | H10: =Bezirk_Absolut!H11/Bezirk_Absolut!$B11 -> 0.20050481 | J10: =Bezirk_Absolut!J11/Bezirk_Absolut!$B11 -> 0.82156757 | K10: =Bezirk_Absolut!K11/Bezirk_Absolut!$B11 -> 0.17843243 | L10: =Bezirk_Absolut!L11/Bezirk_Absolut!$B11 -> 0.72304302 | M10: =Bezirk_Absolut!M11/Bezirk_Absolut!$B11 -> 0.27695698 | N10: =Bezirk_Absolut!N11/Bezirk_Absolut!$B11 -> 0.098524544 | O10: =Bezirk_Absolut!O11/Bezirk_Absolut!$B11 -> 0.5218246 | P10: =Bezirk_Absolut!P11/Bezirk_Absolut!$B11 -> 0.33757756 | Q10: =Bezirk_Absolut!Q11/Bezirk_Absolut!$B11 -> 0.056867513 | ... Y10: =Bezirk_Absolut!Y11/Bezirk_Absolut!$B11 -> 0.060276987
A11: 10 | B11: =Bezirk_Absolut!B12/Bezirk_Absolut!$B12 -> 1 | C11: =Bezirk_Absolut!C12/Bezirk_Absolut!$B12 -> 0.49865346 | D11: =Bezirk_Absolut!D12/Bezirk_Absolut!$B12 -> 0.50134654 | E11: =Bezirk_Absolut!E12/Bezirk_Absolut!$B12 -> 0.15338724 | F11: =Bezirk_Absolut!F12/Bezirk_Absolut!$B12 -> 0.3805829 | G11: =Bezirk_Absolut!G12/Bezirk_Absolut!$B12 -> 0.24408215 | H11: =Bezirk_Absolut!H12/Bezirk_Absolut!$B12 -> 0.22194771 | J11: =Bezirk_Absolut!J12/Bezirk_Absolut!$B12 -> 0.79800935 | K11: =Bezirk_Absolut!K12/Bezirk_Absolut!$B12 -> 0.20199065 | L11: =Bezirk_Absolut!L12/Bezirk_Absolut!$B12 -> 0.68533168 | M11: =Bezirk_Absolut!M12/Bezirk_Absolut!$B12 -> 0.31466832 | N11: =Bezirk_Absolut!N12/Bezirk_Absolut!$B12 -> 0.11267767 | O11: =Bezirk_Absolut!O12/Bezirk_Absolut!$B12 -> 0.49894333 | P11: =Bezirk_Absolut!P12/Bezirk_Absolut!$B12 -> 0.35524644 | Q11: =Bezirk_Absolut!Q12/Bezirk_Absolut!$B12 -> 0.054855791 | ... Y11: =Bezirk_Absolut!Y12/Bezirk_Absolut!$B12 -> 0.038505226
A12: 11 | B12: =Bezirk_Absolut!B13/Bezirk_Absolut!$B13 -> 1 | C12: =Bezirk_Absolut!C13/Bezirk_Absolut!$B13 -> 0.49770157 | D12: =Bezirk_Absolut!D13/Bezirk_Absolut!$B13 -> 0.50229843 | E12: =Bezirk_Absolut!E13/Bezirk_Absolut!$B13 -> 0.14730363 | F12: =Bezirk_Absolut!F13/Bezirk_Absolut!$B13 -> 0.44084886 | G12: =Bezirk_Absolut!G13/Bezirk_Absolut!$B13 -> 0.22402054 | H12: =Bezirk_Absolut!H13/Bezirk_Absolut!$B13 -> 0.18782697 | J12: =Bezirk_Absolut!J13/Bezirk_Absolut!$B13 -> 0.74269546 | K12: =Bezirk_Absolut!K13/Bezirk_Absolut!$B13 -> 0.25730454 | L12: =Bezirk_Absolut!L13/Bezirk_Absolut!$B13 -> 0.61406833 | M12: =Bezirk_Absolut!M13/Bezirk_Absolut!$B13 -> 0.38593167 | N12: =Bezirk_Absolut!N13/Bezirk_Absolut!$B13 -> 0.12862713 | O12: =Bezirk_Absolut!O13/Bezirk_Absolut!$B13 -> 0.55742614 | P12: =Bezirk_Absolut!P13/Bezirk_Absolut!$B13 -> 0.3087843 | Q12: =Bezirk_Absolut!Q13/Bezirk_Absolut!$B13 -> 0.050863914 | ... Y12: =Bezirk_Absolut!Y13/Bezirk_Absolut!$B13 -> 0.052240143
A13: 12 | B13: =Bezirk_Absolut!B14/Bezirk_Absolut!$B14 -> 1 | C13: =Bezirk_Absolut!C14/Bezirk_Absolut!$B14 -> 0.49529907 | D13: =Bezirk_Absolut!D14/Bezirk_Absolut!$B14 -> 0.50470093 | E13: =Bezirk_Absolut!E14/Bezirk_Absolut!$B14 -> 0.14005998 | F13: =Bezirk_Absolut!F14/Bezirk_Absolut!$B14 -> 0.37249361 | G13: =Bezirk_Absolut!G14/Bezirk_Absolut!$B14 -> 0.2564847 | H13: =Bezirk_Absolut!H14/Bezirk_Absolut!$B14 -> 0.23096171 | J13: =Bezirk_Absolut!J14/Bezirk_Absolut!$B14 -> 0.7685636 | K13: =Bezirk_Absolut!K14/Bezirk_Absolut!$B14 -> 0.2314364 | L13: =Bezirk_Absolut!L14/Bezirk_Absolut!$B14 -> 0.57998933 | M13: =Bezirk_Absolut!M14/Bezirk_Absolut!$B14 -> 0.42001067 | N13: =Bezirk_Absolut!N14/Bezirk_Absolut!$B14 -> 0.18857427 | O13: =Bezirk_Absolut!O14/Bezirk_Absolut!$B14 -> 0.47734172 | P13: =Bezirk_Absolut!P14/Bezirk_Absolut!$B14 -> 0.36636308 | Q13: =Bezirk_Absolut!Q14/Bezirk_Absolut!$B14 -> 0.064274806 | ... Y13: =Bezirk_Absolut!Y14/Bezirk_Absolut!$B14 -> 0.10855734
A14: 00 | B14: =Bezirk_Absolut!B15/Bezirk_Absolut!$B15 -> 1 | C14: =Bezirk_Absolut!C15/Bezirk_Absolut!$B15 -> 0.49587418 | D14: =Bezirk_Absolut!D15/Bezirk_Absolut!$B15 -> 0.50412582 | E14: =Bezirk_Absolut!E15/Bezirk_Absolut!$B15 -> 0.13393579 | F14: =Bezirk_Absolut!F15/Bezirk_Absolut!$B15 -> 0.4237575 | G14: =Bezirk_Absolut!G15/Bezirk_Absolut!$B15 -> 0.25126557 | H14: =Bezirk_Absolut!H15/Bezirk_Absolut!$B15 -> 0.19104114 | J14: =Bezirk_Absolut!J15/Bezirk_Absolut!$B15 -> 0.75050899 | K14: =Bezirk_Absolut!K15/Bezirk_Absolut!$B15 -> 0.24949101 | L14: =Bezirk_Absolut!L15/Bezirk_Absolut!$B15 -> 0.57707114 | M14: =Bezirk_Absolut!M15/Bezirk_Absolut!$B15 -> 0.42292886 | N14: =Bezirk_Absolut!N15/Bezirk_Absolut!$B15 -> 0.17343785 | O14: =Bezirk_Absolut!O15/Bezirk_Absolut!$B15 -> 0.53933802 | P14: =Bezirk_Absolut!P15/Bezirk_Absolut!$B15 -> 0.32617147 | Q14: =Bezirk_Absolut!Q15/Bezirk_Absolut!$B15 -> 0.049462598 | ... Y14: =Bezirk_Absolut!Y15/Bezirk_Absolut!$B15 -> 0.20393091
